Workbook

Sheet Inputs
A1: MULTIFAMILY BACKWARD ANALYSIS — ALL INPUTS
A3: RETIREMENT GOALS
A4: Annual passive income (after-tax) | B4: 200000
A5: Timeline to retirement (years) | B5: 5
A6: Min cash-on-cash return | B6: 0.1
A7: Number of properties at retirement | B7: 3
A8: Effective tax rate | B8: 0.3
A9: Cash available for first deal | B9: 150000
A11: DEBT ASSUMPTIONS
A12: LTV - Minimum | B12: 0.65
A13: LTV - Target | B13: 0.75
A14: LTV - Maximum | B14: 0.8
A15: DSCR Required | B15: 1.25
A16: Interest Rate | B16: 0.065
A17: Amortization (years) | B17: 30
A18: Loan Term (years) | B18: 7
A19: Origination Costs % | B19: 0.025
A21: MARKET ASSUMPTIONS
A22: Avg market rent per unit (monthly) | B22: 1200
A23: Avg unit square footage | B23: 850
A24: Vacancy rate | B24: 0.07
A25: Expense ratio (% of EGI) | B25: 0.45
A26: Annual rent growth | B26: 0.03
A27: Annual expense growth | B27: 0.025
A28: Market cap rate | B28: 0.065
A29: Exit cap rate (conservative) | B29: 0.07
A31: INVESTOR / SYNDICATION ASSUMPTIONS
A32: Preferred return to LPs | B32: 0.08
A33: Target equity multiple | B33: 2
A34: Target IRR to LPs | B34: 0.17
A35: Hold period (years) | B35: 5
A36: GP promote after pref | B36: 0.3
A37: Min investment per LP | B37: 50000
A38: Reserve months (operating) | B38: 6
A40: CREATIVE FINANCING ASSUMPTIONS
A41: Seller finance rate | B41: 0.05
A42: Seller finance term (years) | B42: 10
A43: Seller balloon year | B43: 5
A44: Seller max LTV carry | B44: 0.85
A45: Max out-of-pocket (creative) | B45: 50000
...

Sheet Retirement Solve
A1: BACKWARD SOLVE: RETIREMENT INCOME TO DEAL SIZE
A4: Target passive income (after-tax) | B4: =Inputs!B4
A5: Effective tax rate | B5: =Inputs!B8
A6: Pre-tax income needed | B6: =B3/(1-B4)
A7: Number of properties | B7: =Inputs!B7
A8: Income needed per property | B8: =B5/B6
A10: Min cash-on-cash return | B10: =Inputs!B6
A11: Equity required per deal | B11: =B7/B9
A12: Total equity needed (all deals) | B12: =B10*B6
A14: Market cap rate | B14: =Inputs!B26
A15: LTV target | B15: =Inputs!B12
A16: Interest rate | B16: =Inputs!B15
A17: Amortization (years) | B17: =Inputs!B16
A19: Monthly rate | B19: =B15/12
A20: Total payments (months) | B20: =B16*12
A21: Annual loan constant (K) | B21: =(B18*(1+B18)^B19/((1+B18)^B19-1))*12
A22: Debt burden factor (LTV*K/Cap) | B22: =B14*B20/B13
A24: REQUIRED NOI PER DEAL | B24: =B7/(1-B21)
A25: PURCHASE PRICE PER DEAL | B25: =B23/B13
A26: LOAN AMOUNT | B26: =B24*B14
A27: ANNUAL DEBT SERVICE | B27: =B25*B20
A28: YEAR 1 CASH FLOW | B28: =B23-B26
A29: DSCR (actual) | B29: =B23/B26
A31: NOI per unit (annual) | B31: =Inputs!B20*12*(1-Inputs!B22)*(1-Inputs!B23)
A32: UNITS NEEDED PER DEAL | B32: =ROUNDUP(B23/B30,0)
A33: PRICE PER UNIT | B33: =B24/B31
A35: Down payment | B35: =B24*(1-B14)
A36: Closing costs | B36: =B25*Inputs!B18
A37: TOTAL CASH TO CLOSE | B37: =B34+B35

Sheet Debt Validation
A1: DEBT & LTV CONSTRAINT VALIDATION
A3: Required NOI (from Retirement tab) | B3: ='Retirement Solve'!B23
A4: Purchase Price | B4: ='Retirement Solve'!B24
A5: Loan Amount at Target LTV | B5: ='Retirement Solve'!B25
A6: Annual Debt Service | B6: ='Retirement Solve'!B26
A8: DSCR (actual) | B8: ='Retirement Solve'!B28
A9: DSCR Required (minimum) | B9: =Inputs!B14
A10: DSCR Pass? | B10: =IF(B8>=B9,"PASS","FAIL")
A12: Max Loan from DSCR | B12: =B3/(B9*'Retirement Solve'!B20)
A13: Max Loan from LTV | B13: =B4*Inputs!B13
A14: Binding Constraint | B14: =IF(B13<B14,"DSCR","LTV")
A15: Implied LTV at DSCR Limit | B15: =B13/B4
A17: — SPREAD ANALYSIS —
A18: Market Cap Rate | B18: =Inputs!B26
A19: Cost of Debt (interest rate) | B19: =Inputs!B15
A20: Spread (Cap - Debt) in bps | B20: =(B19-B20)*10000
A21: Spread Assessment | B21: =IF(B21>=100,"POSITIVE LEVERAGE",IF(B21>=0,"NEUTRAL","NEGATIVE LEVERAGE"))
A23: — BREAKEVEN ANALYSIS —
A24: Gross Potential Income | B24: =B3/((1-Inputs!B22)*(1-Inputs!B23))
A25: Fixed Expenses | B25: =B25*Inputs!B23
A26: Breakeven Occupancy | B26: =(B6+B26)/B25
A28: — STRESS TEST: Rates +150bps at Refi —
A29: Stress Rate | B29: =Inputs!B15+0.015
A30: NOI at Refi (grown) | B30: =B3*(1+Inputs!B24)^Inputs!B17
A31: Stress DSCR | B31: =B31/B6
A32: Stress Cash Flow | B32: =B31-B6
A33: Stress Test Pass? | B33: =IF(B32>=1.0,"PASS","FAIL")
A35: ═══ VERDICT ═══
A36: Conventional Viable? | B36: =IF(AND(B10="PASS",B21>=0),"CONVENTIONAL FINANCING VIABLE","CREATIVE STRUCTURE REQUIRED")

Sheet Investor Analysis
A1: INVESTOR MARKETABILITY — SYNDICATION FEASIBILITY
A3: Down payment | B3: ='Retirement Solve'!B34
A4: Closing costs | B4: ='Retirement Solve'!B35
A5: Capex budget (units * capex/unit) | B5: ='Retirement Solve'!B31*Inputs!B48
A6: Operating reserves (months) | B6: =('Retirement Solve'!B26/12)*Inputs!B40
A7: TOTAL CAPITAL RAISE | B7: =B3+B4+B5+B6
A9: GP co-invest (your cash) | B9: =Inputs!B9
A10: LP equity needed | B10: =B7-B9
A11: Investors needed (@ min investment) | B11: =ROUNDUP(B10/Inputs!B39,0)
A13: — LP RETURN TARGETS —
A14: Preferred return | B14: =Inputs!B34
A15: Target equity multiple | B15: =Inputs!B35
A16: Target IRR | B16: =Inputs!B36
A17: GP promote after pref | B17: =Inputs!B38
A18: Hold period | B18: =Inputs!B37
A21: ANNUAL CASH FLOW PROJECTION
A22: Year | B22: NOI | C22: Debt Service | D22: Total CF | E22: LP Share | F22: GP Share
A23: 1 | B23: ='Retirement Solve'!B23*(1+Inputs!B24)^1+'Retirement Solve'!B31*Inputs!B49*12*(1-Inputs!B23)*1/5 | C23: ='Retirement Solve'!B26 | D23: =B23-C23 | E23: =D23*(1-Inputs!B38) | F23: =D23*Inputs!B38
A24: 2 | B24: ='Retirement Solve'!B23*(1+Inputs!B24)^2+'Retirement Solve'!B31*Inputs!B49*12*(1-Inputs!B23)*2/5 | C24: ='Retirement Solve'!B26 | D24: =B24-C24 | E24: =D24*(1-Inputs!B38) | F24: =D24*Inputs!B38
A25: 3 | B25: ='Retirement Solve'!B23*(1+Inputs!B24)^3+'Retirement Solve'!B31*Inputs!B49*12*(1-Inputs!B23)*3/5 | C25: ='Retirement Solve'!B26 | D25: =B25-C25 | E25: =D25*(1-Inputs!B38) | F25: =D25*Inputs!B38
A26: 4 | B26: ='Retirement Solve'!B23*(1+Inputs!B24)^4+'Retirement Solve'!B31*Inputs!B49*12*(1-Inputs!B23)*4/5 | C26: ='Retirement Solve'!B26 | D26: =B26-C26 | E26: =D26*(1-Inputs!B38) | F26: =D26*Inputs!B38
A27: 5 | B27: ='Retirement Solve'!B23*(1+Inputs!B24)^5+'Retirement Solve'!B31*Inputs!B49*12*(1-Inputs!B23)*5/5 | C27: ='Retirement Solve'!B26 | D27: =B27-C27 | E27: =D27*(1-Inputs!B38) | F27: =D27*Inputs!B38
A29: EXIT ANALYSIS
A30: Stabilized NOI (Year 5) | B30: =B27
A31: Exit cap rate | B31: =Inputs!B27
A32: Gross exit value | B32: =B30/B31
A33: Less: disposition costs (3%) | B33: =B32*0.03
A34: Less: remaining loan balance (approx) | B34: ='Retirement Solve'!B25*0.90
A35: NET SALE PROCEEDS | B35: =B32-B33-B34
A37: LP exit share | B37: =B35*(1-Inputs!B38)
A38: GP exit share (promote) | B38: =B35*Inputs!B38
A40: LP total distributions | B40: =B37+SUMPRODUCT(E22:E26)
A41: LP EQUITY MULTIPLE | B41: =B40/B10
A44: MARKETABILITY VERDICT
A45: Can raise in 60 days? | B45: =IF(B42>=Inputs!B35,"YES - Deal is marketable","DIFFICULT - Rework returns")

Sheet Creative Financing
A1: CREATIVE FINANCING FEASIBILITY
A3: SELLER FINANCING
A4: Purchase price | B4: ='Retirement Solve'!B24
A5: Seller carry LTV | B5: =Inputs!B44
A6: Seller carry amount | B6: =B4*B5
A7: Down payment to seller | B7: =B4-B6
A8: Seller finance rate | B8: =Inputs!B42
A9: Seller finance term (years) | B9: =Inputs!B43
A10: Monthly payment (seller note) | B10: =PMT(B8/12,B9*12,-B6)
A11: Annual debt service (seller) | B11: =B10*12
A12: NOI | B12: ='Retirement Solve'!B23
A13: Cash flow (seller finance) | B13: =B12-B11
A14: DSCR (seller note) | B14: =B12/B11
A15: Balloon year | B15: =Inputs!B45
A16: Balloon balance (approx) | B16: =B6*0.85
A18: Seller finance VIABLE? | B18: =IF(AND(B13>0,B14>=1.1),"YES","NO")
A20: SUBJECT-TO / WRAP
A21: Estimated existing debt (50% of price) | B21: ='Retirement Solve'!B24*0.50
A22: Existing rate (assumed) | B22: 0.045
A23: Existing annual debt service | B23: =PMT(B22/12,25*12,-B21)*12
A24: Gap financing needed | B24: =B4-B21-Inputs!B46
A25: Cash flow (sub-to) | B25: ='Retirement Solve'!B23-B23
A26: Gap < 20% of price? | B26: =IF(B24<B4*0.2,"YES","NO")
A27: Subject-to VIABLE? | B27: =IF(AND(B25>0,B26="YES"),"YES","NO")
A28: Due-on-sale risk | B28: MODERATE
A30: MASTER LEASE WITH OPTION
A31: Seller's debt service (existing) | B31: =B23
A32: Master lease payment (110% of seller DS) | B32: =B31*1.10
A33: Monthly lease payment | B33: =B32/12
A34: Cash flow during lease | B34: ='Retirement Solve'!B23-B32
A35: Option strike price (price + premium) | B35: =B4*(1+Inputs!B47)
A36: Stabilized NOI post-reno | B36: ='Retirement Solve'!B23+'Retirement Solve'!B31*Inputs!B49*12*(1-Inputs!B23)
A37: Refi value at market cap | B37: =B36/Inputs!B26
A38: Refi loan at 75% LTV | B38: =B37*0.75
A39: Can cash-out refi to exercise? | B39: =IF(B38>=B35,"YES","NO")
A40: Master lease VIABLE? | B40: =IF(AND(B34>0,B39="YES"),"YES","NO")
A43: ═══ CREATIVE VERDICT ═══
A44: Best creative structure | B44: =IF(B18="YES","SELLER FINANCING",IF(B27="YES","SUBJECT-TO",IF(B40="YES","MASTER LEASE","NONE")))
A45: Minimum out-of-pocket | B45: =IF(B18="YES",B7,IF(B27="YES",Inputs!B46,IF(B40="YES",B33*2,B7)))

Sheet Deal Criteria
A1: ACQUISITION CRITERIA BOX
A3: Parameter | B3: Minimum | C3: Target | D3: Maximum
A4: Unit count | B4: =ROUNDUP('Retirement Solve'!B31*0.7,0) | C4: ='Retirement Solve'!B31 | D4: =ROUNDUP('Retirement Solve'!B31*1.5,0)
A5: Purchase price | B5: ='Retirement Solve'!B24*0.75 | C5: ='Retirement Solve'!B24 | D5: ='Retirement Solve'!B24*1.15
A6: Going-in cap rate | B6: =Inputs!B26-0.005 | C6: =Inputs!B26 | D6: =Inputs!B26+0.02
A7: Price per unit | B7: ='Retirement Solve'!B24*0.75/'Retirement Solve'!B31 | C7: ='Retirement Solve'!B32 | D7: ='Retirement Solve'!B24*1.15/ROUNDUP('Retirement Solve'!B31*0.7,0)
A8: Price per SF | B8: ='Retirement Solve'!B24*0.75/('Retirement Solve'!B31*Inputs!B21) | C8: ='Retirement Solve'!B24/('Retirement Solve'!B31*Inputs!B21) | D8: ='Retirement Solve'!B24*1.15/(ROUNDUP('Retirement Solve'!B31*0.7,0)*Inputs!B21)
A9: Current occupancy | B9: 80% | C9: 90% | D9: —
A10: In-place NOI | B10: ='Retirement Solve'!B23*0.70 | C10: ='Retirement Solve'!B23 | D10: —
A11: Stabilized NOI (post-reno) | B11: ='Retirement Solve'!B23 | C11: ='Retirement Solve'!B23*1.20 | D11: —
A12: Rent upside/unit (monthly) | B12: $100 | C12: =Inputs!B49 | D12: —
A13: Total capex budget | B13: ='Retirement Solve'!B31*Inputs!B48*0.5 | C13: ='Retirement Solve'!B31*Inputs!B48 | D13: ='Retirement Solve'!B31*Inputs!B48*1.5
A14: Capex per unit | B14: =Inputs!B48*0.5 | C14: =Inputs!B48 | D14: =Inputs!B48*1.5
A15: Year 1 Cash-on-Cash | B15: =Inputs!B6*0.8 | C15: =Inputs!B6 | D15: —
A16: 5-Year IRR (levered) | B16: 14% | C16: 18% | D16: —
A17: Exit cap rate | B17: =Inputs!B27-0.005 | C17: =Inputs!B27 | D17: =Inputs!B27+0.015
A18: Max OOP (creative) | B18: $0 | C18: =Inputs!B46 | D18: =Inputs!B46*3
A19: Capital raise (syndication) | B19: ='Investor Analysis'!B7*0.8 | C19: ='Investor Analysis'!B7 | D19: ='Investor Analysis'!B7*1.3

Sheet Scenarios
A1: SCENARIO & SENSITIVITY ANALYSIS
A3: SCENARIO PARAMETERS
A4: Parameter | B4: BULL | C4: BASE | D4: BEAR | E4: CATASTROPHE
A5: Rent growth override | B5: 4.0% | C5: 3.0% | D5: 0.5% | E5: -1.0%
A6: Value-add achieved | B6: 100% | C6: 80% | D6: 50% | E6: 30%
A7: Exit cap rate | B7: 6.0% | C7: 7.0% | D7: 8.5% | E7: 9.5%
A8: Vacancy override | B8: 5.0% | C8: 7.0% | D8: 10.0% | E8: 14.0%
A9: Rate change at refi | B9: -0.5% | C9: 0.0% | D9: +1.0% | E9: +2.0%
A12: SCENARIO RESULTS (5-Year Hold)
A13: Metric | B13: BULL | C13: BASE | D13: BEAR | E13: CATASTROPHE
A14: NOI at Exit | B14: ='Retirement Solve'!B23*(1.04)^5+'Retirement Solve'!B31*Inputs!B49*12*(1-Inputs!B23)*1.0 | C14: ='Retirement Solve'!B23*(1.03)^5+'Retirement Solve'!B31*Inputs!B49*12*(1-Inputs!B23)*0.8 | D14: ='Retirement Solve'!B23*(1.005)^5+'Retirement Solve'!B31*Inputs!B49*12*(1-Inputs!B23)*0.5 | E14: ='Retirement Solve'!B23*(0.99)^5+'Retirement Solve'!B31*Inputs!B49*12*(1-Inputs!B23)*0.3
A15: Exit Value | B15: =B14/0.06 | C15: =C14/0.07 | D15: =D14/0.085 | E15: =E14/0.095
A16: Net Proceeds (after loan payoff) | B16: =B15*0.97-'Retirement Solve'!B25*0.90 | C16: =C15*0.97-'Retirement Solve'!B25*0.90 | D16: =D15*0.97-'Retirement Solve'!B25*0.90 | E16: =E15*0.97-'Retirement Solve'!B25*0.90
A17: Avg Annual CF | B17: =('Retirement Solve'!B23+B14)/2-'Retirement Solve'!B26 | C17: =('Retirement Solve'!B23+C14)/2-'Retirement Solve'!B26 | D17: =('Retirement Solve'!B23+D14)/2-'Retirement Solve'!B26 | E17: =('Retirement Solve'!B23+E14)/2-'Retirement Solve'!B26
A18: Meets Retirement Goal? | B18: =IF(B17*Inputs!B7>=Inputs!B4/(1-Inputs!B8),"YES","NO") | C18: =IF(C17*Inputs!B7>=Inputs!B4/(1-Inputs!B8),"YES","NO") | D18: =IF(D17*Inputs!B7>=Inputs!B4/(1-Inputs!B8),"YES","NO") | E18: =IF(E17*Inputs!B7>=Inputs!B4/(1-Inputs!B8),"YES","NO")
A19: Deal Survives? | B19: =IF(AND(B17>0,B16>0),"YES","NO") | C19: =IF(AND(C17>0,C16>0),"YES","NO") | D19: =IF(AND(D17>0,D16>0),"YES","NO") | E19: =IF(AND(E17>0,E16>0),"YES","NO")

Sheet Decision
A1: DECISION FRAMEWORK — GO / NO-GO / NEGOTIATE
A3: SCORECARD
A4: Criterion | B4: Result | C4: Notes
A5: Conventional financing viable | B5: ='Debt Validation'!B37 | C5: Requires positive spread + DSCR >= 1.25x
A6: Investor marketability grade | B6: =IF('Investor Analysis'!B7>0,"MARKETABLE","NOT MARKETABLE") | C6: Needs 8%+ pref, 2.0x multiple, 17%+ IRR
A7: Creative structure available | B7: ='Creative Financing'!B44 | C7: Seller finance, sub-to, or master lease
A8: Bear case survives | B8: =Scenarios!D19 | C8: Positive CF and equity at exit in bear scenario
A9: Catastrophe survival | B9: =Scenarios!E19 | C9: Can survive rate spike + rent decline
A10: Meets retirement goal (base) | B10: =Scenarios!C18 | C10: Cash flow * num properties >= income target
A13: ═══ FINAL DECISION ═══
A14: DECISION: | B14: =IF(AND(B5="CONVENTIONAL FINANCING VIABLE",B8="YES",B10="YES"),"GO (CONVENTIONAL)",IF(AND(OR(B7<>"NONE",B5="CONVENTIONAL FINANCING VIABLE"),B8="YES"),"GO (CREATIVE)",IF(AND(B8="NO",Scenarios!C19="YES"),"NEGOTIATE — Need price reduction for safety margin","NO-GO — Pass on this deal")))
A16: DECISION DEFINITIONS:
A17: GO (CONVENTIONAL): Deal hits all metrics with standard agency debt + investor raise
A18: GO (CREATIVE): Deal requires creative structure but math works and seller profile fits
A19: NEGOTIATE: Deal works at lower price or with seller concession — counter required
A20: NO-GO: Spread too thin, returns don't justify risk, can't market to investors
